<!DOCTYPE html>
<html lang="en">
<head>
    <meta charset="UTF-8">
    <meta name="viewport" content="width=device-width, initial-scale=1.0">
    <title>购物车</title>
    <script src="js/vue.js"></script>
    <style>
        .active {
            background-color: #dddddd;
        }
    </style>
</head>

<body>
    <!-- 宿主文件 -->
    <div id="app">
        <h2>
            <!-- 插值文本 -->
            {{title}}
        </h2>
        <hr>
        <div v-for="c in course" :key="c" :class="{active: selectedCourse === c}" @click="selectedCourse = c">
            {{c}}
        </div>
        <hr>
        <p>一共{{total}}课程</p>
        <input type="text" v-model="coursename" v-on:keydown.enter="addCourse">
        <div v-text="coursename"></div>

    </div>
</body>
<script>
    // 创建实例
    const app = new Vue({
        el: '#app',
        data() {
            return {
                title: '购物车',
                date: new Date(),
                course: [
                    'vue',
                    'node'
                ],
                coursename: '',
                selectedCourse: null,
            }
        },
        mounted () {

            // 未使用catch捕获异常/通过then的两个函数参数，来处理指定状态(resolved/rejected)
            // this.asyncThing().then((val) => {
            //     console.info('result: ' + val)
            // }, (err) => {
            //     console.log(err);
            // });

            // 使用catch捕获异常后，异常不会抛出在控制台
            // catch 只能捕获catch之前的错误，之后出现的错误还需要catch(冒泡性质向后传递异常)
            this.asyncThing().then((val) => {
                console.info('result: ' + val)
            }).catch((error) => {
                console.log('throw err: ' + error);
                console.info(y+2)
            }).then(() => {
                console.log('catch后可以继续then() ');
            }).catch((err) => {
                console.log('throw err2: ' + err);
            }).finally(() => {
                console.log('finally.....');
            })

            setTimeout(() => {
                console.info('setTimeout......')
            }, 2000);
        },
        methods: {
            asyncThing: () => {
                // 这里x为定义，且为使用promise捕获异常，异常信息会直接抛出。
                return new Promise((resolve, reject) => {
                    resolve(x, 2);
                    // promise可以使用then作为回调函数来处理reslove/reject
                });
            },
            addCourse(e) {
                this.course.push(this.coursename);
                let unique = new Set(this.course);
                this.course = [...unique];

            }
        },
        watch: {
            course: {
                immediate: true,
                deep: true,
                handler(newValue, oldValue) {
                    console.info(newValue)
                }
            }
        },
        computed: {
            total() {
                return this.course.length + '门'; 
            }
        }
    });
</script>

</html>